Workbook
Name _Toc168593517: Hoja1!$A$2

Sheet Hoja1
A2: 1. Criterios de valoración y puntuaciones. | G2: =Aux!B2 -> Equipo 1 | J2: =Aux!B3 -> Equipo 2 | M2: 3 Lugar
C4: Criterio | D4: Peso [%] | E4: Evaluación | G4: Criterio | H4: Puntos | J4: Criterio | K4: Puntos | M4: Criterio | N4: Peso [%]
C5: Diseño conceptual | D5: 30 | E5: Jurado | G5: Diseño conceptual | H5: =_xlfn.XLOOKUP(G2,E15:E21,D15:D21) -> 30 | J5: Diseño conceptual | K5: =_xlfn.XLOOKUP(J2,H15:H21,G15:G21) -> #N/A | M5: Diseño conceptual | N5: =D17 -> 22
C6: Exposición de la solución | D6: 20 | G6: Exposición de la solución | H6: =_xlfn.XLOOKUP(G2,E25:E31,D25:D31) -> 20 | J6: Exposición de la solución | K6: =_xlfn.XLOOKUP(J2,H25:H31,G25:G31) -> #N/A | M6: Exposición de la solución | N6: =D27 -> 14
C7: Peso de la estructura | D7: 20 | E7: Báscula | G7: Peso de la estructura | H7: =_xlfn.XLOOKUP(G2,E39:E45,D39:D45) -> 20 | J7: Peso de la estructura | K7: =_xlfn.XLOOKUP(J2,H39:H45,G39:G45) -> #N/A | M7: Peso de la estructura | N7: =D41 -> 14
C8: Capacidad de carga | D8: 15 | E8: Ensayo de carga | G8: Capacidad de carga | H8: =_xlfn.XLOOKUP(G2,C49:C55,E49:E55) -> 1 | J8: Capacidad de carga | K8: =_xlfn.XLOOKUP(J2,F49:F55,H49:H55) -> #N/A | M8: Capacidad de carga | N8: =I52 -> 10
C9: Deformación | D9: 15 | G9: Deformación | H9: =_xlfn.XLOOKUP(G2,C59:C65,F59:F65) -> 15 | J9: Deformación | K9: =_xlfn.XLOOKUP(J2,F59:F65,I59:I65) -> #N/A | M9: Deformación | N9: =K52 -> 10
C10: Total | D10: =SUM(D5:D9) -> 100 | G10: Total | H10: =SUM(H5:H9) -> 86 | J10: Total | K10: =SUM(K5:K9) -> #N/A | M10: Total | N10: =SUM(N5:N9) -> 70
C12: Diseño conceptual (30 puntos)
C14: Posición | D14: Puntos | E14: Equipo
C15: 1º | D15: 30 | E15: Equipo 1
C16: 2º | D16: 26 | E16: Equipo 5
C17: 3º | D17: 22 | E17: Equipo 5
C18: 4º | D18: 19 | E18: Equipo 1
C19: 5º | D19: 17 | E19: Equipo 3
C20: 6º | D20: 15 | E20: Equipo 3
C21: 7º | D21: 15 | E21: Equipo 3
C23: Exposición de la solución (20 puntos)
C24: Posición | D24: Puntos
C25: 1º | D25: 20 | E25: Equipo 1
C26: 2º | D26: 17 | E26: Equipo 5 | H26: Deformación/Rigidez (15 puntos)
C27: 3º | D27: 14 | E27: Equipo 5
C28: 4º | D28: 12 | E28: Equipo 1
C29: 5º | D29: 11 | E29: Equipo 3
C30: 6º | D30: 10 | E30: Equipo 3
C31: 7º | D31: 10 | E31: Equipo 3
C34: Peso de la estructura (20 puntos)
C35: Su peso se redondeará a la medida más cercana en múltiplos de 100 g. Se dará la puntuación máxima de 20 puntos a la que menos pese, y 0 puntos a la que más.
C38: Posición | D38: Puntos | E38: Equipo
C39: 1º | D39: 20 | E39: Equipo 1
C40: 2º | D40: 17 | E40: Equipo 5
C41: 3º | D41: 14 | E41: Equipo 5
C42: 4º | D42: 12 | E42: Equipo 1
C43: 5º | D43: 11 | E43: Equipo 3
C44: 6º | D44: 10 | E44: Equipo 3
C45: 7º | D45: 10 | E45: Equipo 3
C47: Capacidad de carga P (kg) (15 puntos)
D48: P (kg) | E48: Puntos
C49: =Aux!B2 -> Equipo 1 | D49: 107 | E49: =IF(D49>=$H$50,$I$50, IF(D49>=$H$51,$I$51, IF(D49>=$H$52,$I$52, IF(D49>=$H$53,$I$53, IF(D49>=$H$54,$I$54, IF(D49>=$H$55,$I$55, IF(D49>=$H$56,$I$56, IF(D49>=$H$57,$I$57, IF(D49>=$H$58,$I$58,0))))))))) -> 1 | H49: Pu [kg] > | I49: Puntos | J49: d500 [mm] < | K49: Puntos
C50: =Aux!B3 -> Equipo 2 | D50: 200 | E50: =IF(D50>=$H$50,$I$50, IF(D50>=$H$51,$I$51, IF(D50>=$H$52,$I$52, IF(D50>=$H$53,$I$53, IF(D50>=$H$54,$I$54, IF(D50>=$H$55,$I$55, IF(D50>=$H$56,$I$56, IF(D50>=$H$57,$I$57, IF(D50>=$H$58,$I$58,0))))))))) -> 3 | H50: 500 | I50: 15 | J50: 30 | K50: 15
...

Sheet Aux
B2: Equipo 1
B3: Equipo 2
B4: Equipo 3
B5: Equipo 4
B6: Equipo 5
B7: Equipo 6
B8: Equipo 7
